Workbook

Sheet MMA301_Assignment1_Plan
A1: ID | B1: Phase | C1: Day | D1: Task | E1: Subtask | F1: Requirement / Rubric liên quan | G1: Screen / File / Component liên quan | H1: Input | I1: Expected Output | J1: Evidence cần lưu | K1: Test cần thực hiện | L1: Interview cần biết | M1: AI có thể hỗ trợ gì | N1: AI Verification | O1: Priority | P1: Estimated Time | Q1: Status | R1: Notes | T1: COLOR LEGEND
A2: P1-01 | B2: Phase 1 – Requirement Analysis | C2: Day 1 | D2: Read PDF end-to-end | E2: Break requirement into a concrete decision/output. | F2: R01–R10; Rubric 1–2 | G2: Requirements / RTM | H2: Assignment PDF + project | I2: Requirement decisions recorded | J2: Notes + RTM draft | K2: Verify against PDF | L2: Requirement → evidence mapping | M2: Checklist/gap scan | N2: Compare with PDF | O2: HIGH | P2: 30 | Q2: DONE | T2: PHASE 1 – UNDERSTAND
A3: P1-02 | B3: Phase 1 – Requirement Analysis | C3: Day 1 | D3: Extract scope, screens, workflow, technical constraints and evidence requirements. | E3: Break requirement into a concrete decision/output. | F3: R01–R10; Rubric 1–2 | G3: Requirements / RTM | H3: Assignment PDF + project | I3: Requirement decisions recorded | J3: Notes + RTM draft | K3: Verify against PDF | L3: Requirement → evidence mapping | M3: Checklist/gap scan | N3: Compare with PDF | O3: HIGH | P3: 30 | Q3: DONE | T3: PHASE 2 – DESIGN
A4: P1-03 | B4: Phase 1 – Requirement Analysis | C4: Day 1 | D4: List screens/navigation | E4: Break requirement into a concrete decision/output. | F4: R01–R10; Rubric 1–2 | G4: Requirements / RTM | H4: Assignment PDF + project | I4: Requirement decisions recorded | J4: Notes + RTM draft | K4: Verify against PDF | L4: Requirement → evidence mapping | M4: Checklist/gap scan | N4: Compare with PDF | O4: HIGH | P4: 30 | Q4: DONE | T4: PHASE 3 – IMPLEMENT
A5: P1-04 | B5: Phase 1 – Requirement Analysis | C5: Day 1 | D5: Home, Profile, Edit Profile, Activity/Interests, Settings and navigation flow. | E5: Break requirement into a concrete decision/output. | F5: R01–R10; Rubric 1–2 | G5: Requirements / RTM | H5: Assignment PDF + project | I5: Requirement decisions recorded | J5: Notes + RTM draft | K5: Verify against PDF | L5: Requirement → evidence mapping | M5: Checklist/gap scan | N5: Compare with PDF | O5: HIGH | P5: 30 | Q5: DONE | T5: PHASE 4 – TEST
A6: P1-05 | B6: Phase 1 – Requirement Analysis | C6: Day 1 | D6: Classify state ownership | E6: Break requirement into a concrete decision/output. | F6: R01–R10; Rubric 1–2 | G6: Requirements / RTM | H6: Assignment PDF + project | I6: Requirement decisions recorded | J6: Notes + RTM draft | K6: Verify against PDF | L6: Requirement → evidence mapping | M6: Checklist/gap scan | N6: Compare with PDF | O6: HIGH | P6: 30 | Q6: DONE | T6: PHASE 5 – REVIEW / COMPLETE
A7: P1-06 | B7: Phase 1 – Requirement Analysis | C7: Day 1 | D7: Mark local UI, shared state, persistent state and hydration. | E7: Break requirement into a concrete decision/output. | F7: R01–R10; Rubric 1–2 | G7: Requirements / RTM | H7: Assignment PDF + project | I7: Requirement decisions recorded | J7: Notes + RTM draft | K7: Verify against PDF | L7: Requirement → evidence mapping | M7: Checklist/gap scan | N7: Compare with PDF | O7: HIGH | P7: 30 | Q7: DONE | T7: TODO / NOT STARTED
A8: P1-07 | B8: Phase 1 – Requirement Analysis | C8: Day 1 | D8: Define Profile model/validation | E8: Break requirement into a concrete decision/output. | F8: R01–R10; Rubric 1–2 | G8: Requirements / RTM | H8: Assignment PDF + project | I8: Requirement decisions recorded | J8: Notes + RTM draft | K8: Verify against PDF | L8: Requirement → evidence mapping | M8: Checklist/gap scan | N8: Compare with PDF | O8: HIGH | P8: 30 | Q8: DONE | T8: IN PROGRESS
A9: P1-08 | B9: Phase 1 – Requirement Analysis | C9: Day 1 | D9: Name/avatar/bio, validation, invalid data must not save. | E9: Break requirement into a concrete decision/output. | F9: R01–R10; Rubric 1–2 | G9: Requirements / RTM | H9: Assignment PDF + project | I9: Requirement decisions recorded | J9: Notes + RTM draft | K9: Verify against PDF | L9: Requirement → evidence mapping | M9: Checklist/gap scan | N9: Compare with PDF | O9: HIGH | P9: 30 | Q9: DONE | T9: BLOCKED
A10: P1-09 | B10: Phase 1 – Requirement Analysis | C10: Day 1 | D10: Define list behavior | E10: Break requirement into a concrete decision/output. | F10: R01–R10; Rubric 1–2 | G10: Requirements / RTM | H10: Assignment PDF + project | I10: Requirement decisions recorded | J10: Notes + RTM draft | K10: Verify against PDF | L10: Requirement → evidence mapping | M10: Checklist/gap scan | N10: Compare with PDF | O10: HIGH | P10: 30 | Q10: DONE | T10: DONE
A11: P1-10 | B11: Phase 1 – Requirement Analysis | C11: Day 1 | D11: Collection shape, stable key, empty state and state-changing interaction. | E11: Break requirement into a concrete decision/output. | F11: R01–R10; Rubric 1–2 | G11: Requirements / RTM | H11: Assignment PDF + project | I11: Requirement decisions recorded | J11: Notes + RTM draft | K11: Verify against PDF | L11: Requirement → evidence mapping | M11: Checklist/gap scan | N11: Compare with PDF | O11: HIGH | P11: 30 | Q11: DONE | T11: LOW
A12: P1-11 | B12: Phase 1 – Requirement Analysis | C12: Day 1 | D12: Define persistence behavior | E12: Break requirement into a concrete decision/output. | F12: R01–R10; Rubric 1–2 | G12: Requirements / RTM | H12: Assignment PDF + project | I12: Requirement decisions recorded | J12: Notes + RTM draft | K12: Verify against PDF | L12: Requirement → evidence mapping | M12: Checklist/gap scan | N12: Compare with PDF | O12: HIGH | P12: 30 | Q12: DONE | T12: MEDIUM
A13: P1-12 | B13: Phase 1 – Requirement Analysis | C13: Day 1 | D13: AsyncStorage keys, JSON serialization, first-run defaults, missing/corrupt fallback. | E13: Break requirement into a concrete decision/output. | F13: R01–R10; Rubric 1–2 | G13: Requirements / RTM | H13: Assignment PDF + project | I13: Requirement decisions recorded | J13: Notes + RTM draft | K13: Verify against PDF | L13: Requirement → evidence mapping | M13: Checklist/gap scan | N13: Compare with PDF | O13: HIGH | P13: 30 | Q13: DONE | T13: HIGH
A14: P1-13 | B14: Phase 1 – Requirement Analysis | C14: Day 1 | D14: Define theme behavior | E14: Break requirement into a concrete decision/output. | F14: R01–R10; Rubric 1–2 | G14: Requirements / RTM | H14: Assignment PDF + project | I14: Requirement decisions recorded | J14: Notes + RTM draft | K14: Verify against PDF | L14: Requirement → evidence mapping | M14: Checklist/gap scan | N14: Compare with PDF | O14: HIGH | P14: 30 | Q14: DONE
A15: P1-14 | B15: Phase 1 – Requirement Analysis | C15: Day 1 | D15: Context placement, app-wide update, hydration and persistence. | E15: Break requirement into a concrete decision/output. | F15: R01–R10; Rubric 1–2 | G15: Requirements / RTM | H15: Assignment PDF + project | I15: Requirement decisions recorded | J15: Notes + RTM draft | K15: Verify against PDF | L15: Requirement → evidence mapping | M15: Checklist/gap scan | N15: Compare with PDF | O15: HIGH | P15: 30 | Q15: DONE
A16: P1-15 | B16: Phase 1 – Requirement Analysis | C16: Day 1 | D16: Map end-to-end workflow | E16: Break requirement into a concrete decision/output. | F16: R01–R10; Rubric 1–2 | G16: Requirements / RTM | H16: Assignment PDF + project | I16: Requirement decisions recorded | J16: Notes + RTM draft | K16: Verify against PDF | L16: Requirement → evidence mapping | M16: Checklist/gap scan | N16: Compare with PDF | O16: HIGH | P16: 30 | Q16: DONE
A17: P1-16 | B17: Phase 1 – Requirement Analysis | C17: Day 1 | D17: Startup → Profile → Edit → Save → Activity → Settings → restart. | E17: Break requirement into a concrete decision/output. | F17: R01–R10; Rubric 1–2 | G17: Requirements / RTM | H17: Assignment PDF + project | I17: Requirement decisions recorded | J17: Notes + RTM draft | K17: Verify against PDF | L17: Requirement → evidence mapping | M17: Checklist/gap scan | N17: Compare with PDF | O17: HIGH | P17: 30 | Q17: DONE
A18: P1-17 | B18: Phase 1 – Requirement Analysis | C18: Day 1 | D18: Identify edge/failure cases | E18: Break requirement into a concrete decision/output. | F18: R01–R10; Rubric 1–2 | G18: Requirements / RTM | H18: Assignment PDF + project | I18: Requirement decisions recorded | J18: Notes + RTM draft | K18: Verify against PDF | L18: Requirement → evidence mapping | M18: Checklist/gap scan | N18: Compare with PDF | O18: HIGH | P18: 30 | Q18: DONE
A19: P1-18 | B19: Phase 1 – Requirement Analysis | C19: Day 1 | D19: Invalid form, empty list, missing/corrupt storage, failed async operation. | E19: Break requirement into a concrete decision/output. | F19: R01–R10; Rubric 1–2 | G19: Requirements / RTM | H19: Assignment PDF + project | I19: Requirement decisions recorded | J19: Notes + RTM draft | K19: Verify against PDF | L19: Requirement → evidence mapping | M19: Checklist/gap scan | N19: Compare with PDF | O19: HIGH | P19: 30 | Q19: DONE
A20: P1-19 | B20: Phase 1 – Requirement Analysis | C20: Day 1 | D20: Create state/data sketch | E20: Break requirement into a concrete decision/output. | F20: R01–R10; Rubric 1–2 | G20: Requirements / RTM | H20: Assignment PDF + project | I20: Requirement decisions recorded | J20: Notes + RTM draft | K20: Verify against PDF | L20: Requirement → evidence mapping | M20: Checklist/gap scan | N20: Compare with PDF | O20: HIGH | P20: 30 | Q20: DONE
A21: P1-20 | B21: Phase 1 – Requirement Analysis | C21: Day 1 | D21: Screen/component/state/data/service relationships. | E21: Break requirement into a concrete decision/output. | F21: R01–R10; Rubric 1–2 | G21: Requirements / RTM | H21: Assignment PDF + project | I21: Requirement decisions recorded | J21: Notes + RTM draft | K21: Verify against PDF | L21: Requirement → evidence mapping | M21: Checklist/gap scan | N21: Compare with PDF | O21: HIGH | P21: 30 | Q21: DONE
A22: P1-21 | B22: Phase 1 – Requirement Analysis | C22: Day 1 | D22: Build initial RTM | E22: Break requirement into a concrete decision/output. | F22: R01–R10; Rubric 1–2 | G22: Requirements / RTM | H22: Assignment PDF + project | I22: Requirement decisions recorded | J22: Notes + RTM draft | K22: Verify against PDF | L22: Requirement → evidence mapping | M22: Checklist/gap scan | N22: Compare with PDF | O22: HIGH | P22: 30 | Q22: DONE
A23: P1-22 | B23: Phase 1 – Requirement Analysis | C23: Day 1 | D23: Map R01–R10 to implementation, tests, evidence, demo and interview. | E23: Break requirement into a concrete decision/output. | F23: R01–R10; Rubric 1–2 | G23: Requirements / RTM | H23: Assignment PDF + project | I23: Requirement decisions recorded | J23: Notes + RTM draft | K23: Verify against PDF | L23: Requirement → evidence mapping | M23: Checklist/gap scan | N23: Compare with PDF | O23: HIGH | P23: 30 | Q23: DONE
A24: P2-01 | B24: Phase 2 – Design | C24: Day 2 | D24: Navigation architecture | E24: Define central navigation and screen responsibilities. | F24: R02–R10; Rubric 2 | G24: Navigation / Context / Components / Storage | H24: Requirement analysis + state sketch | I24: Design ready | J24: Diagram/notes + DDD | K24: Walk through design | L24: Explain why state belongs where | M24: Keep only verified decisions | N24: HIGH | O24: 30 | P24: TODO | Q24: DONE
A25: P2-02 | B25: Phase 2 – Design | C25: Day 2 | D25: Screen/component structure | E25: Create component tree for Home, Profile, Edit Profile, Activity, Settings. | F25: R02–R10; Rubric 2 | G25: Navigation / Context / Components / Storage | H25: Requirement analysis + state sketch | I25: Design ready | J25: Diagram/notes + DDD | K25: Walk through design | L25: Explain why state belongs where | M25: Keep only verified decisions | N25: HIGH | O25: 30 | P25: TODO | Q25: DONE
A26: P2-03 | B26: Phase 2 – Design | C26: Day 2 | D26: State ownership design | E26: Decide local vs shared state with explicit ownership. | F26: R02–R10; Rubric 2 | G26: Navigation / Context / Components / Storage | H26: Requirement analysis + state sketch | I26: Design ready | J26: Diagram/notes + DDD | K26: Walk through design | L26: Explain why state belongs where | M26: Keep only verified decisions | N26: HIGH | O26: 30 | P26: TODO | Q26: DONE
A27: P2-04 | B27: Phase 2 – Design | C27: Day 2 | D27: ThemeContext design | E27: Define provider value, toggle/update and re-render expectations. | F27: R02–R10; Rubric 2 | G27: Navigation / Context / Components / Storage | H27: Requirement analysis + state sketch | I27: Design ready | J27: Diagram/notes + DDD | K27: Walk through design | L27: Explain why state belongs where | M27: Keep only verified decisions | N27: HIGH | O27: 30 | P27: TODO | Q27: DONE
A28: P2-05 | B28: Phase 2 – Design | C28: Day 2 | D28: Profile state design | E28: Define shared profile state and immediate UI update after save. | F28: R02–R10; Rubric 2 | G28: Navigation / Context / Components / Storage | H28: Requirement analysis + state sketch | I28: Design ready | J28: Diagram/notes + DDD | K28: Walk through design | L28: Explain why state belongs where | M28: Keep only verified decisions | N28: HIGH | O28: 30 | P28: TODO | Q28: DONE
A29: P2-06 | B29: Phase 2 – Design | C29: Day 2 | D29: Persistence architecture | E29: Define AsyncStorage helper, keys, serialization and hydration. | F29: R02–R10; Rubric 2 | G29: Navigation / Context / Components / Storage | H29: Requirement analysis + state sketch | I29: Design ready | J29: Diagram/notes + DDD | K29: Walk through design | L29: Explain why state belongs where | M29: Keep only verified decisions | N29: HIGH | O29: 30 | P29: TODO | Q29: DONE
A30: P2-07 | B30: Phase 2 – Design | C30: Day 2 | D30: Hydration timing | E30: Startup loading/default strategy and corrupt-data fallback. | F30: R02–R10; Rubric 2 | G30: Navigation / Context / Components / Storage | H30: Requirement analysis + state sketch | I30: Design ready | J30: Diagram/notes + DDD | K30: Walk through design | L30: Explain why state belongs where | M30: Keep only verified decisions | N30: HIGH | O30: 30 | P30: TODO | Q30: DONE
A31: P2-08 | B31: Phase 2 – Design | C31: Day 2 | D31: List design | E31: FlatList/SectionList data, renderItem, keyExtractor and empty state. | F31: R02–R10; Rubric 2 | G31: Navigation / Context / Components / Storage | H31: Requirement analysis + state sketch | I31: Design ready | J31: Diagram/notes + DDD | K31: Walk through design | L31: Explain why state belongs where | M31: Keep only verified decisions | N31: HIGH | O31: 30 | P31: TODO | Q31: DONE
A32: P2-09 | B32: Phase 2 – Design | C32: Day 2 | D32: Reusable components | E32: Identify reusable buttons, inputs, cards and list items. | F32: R02–R10; Rubric 2 | G32: Navigation / Context / Components / Storage | H32: Requirement analysis + state sketch | I32: Design ready | J32: Diagram/notes + DDD | K32: Walk through design | L32: Explain why state belongs where | M32: Keep only verified decisions | N32: HIGH | O32: 30 | P32: TODO | Q32: DONE
A33: P2-10 | B33: Phase 2 – Design | C33: Day 2 | D33: Validation/error design | E33: Validation rules, errors, save/cancel and failure paths. | F33: R02–R10; Rubric 2 | G33: Navigation / Context / Components / Storage | H33: Requirement analysis + state sketch | I33: Design ready | J33: Diagram/notes + DDD | K33: Walk through design | L33: Explain why state belongs where | M33: Keep only verified decisions | N33: HIGH | O33: 30 | P33: TODO | Q33: DONE
A34: P2-11 | B34: Phase 2 – Design | C34: Day 2 | D34: Folder structure | E34: Screens / Components / Context / Services(or utils) organization. | F34: R02–R10; Rubric 2 | G34: Navigation / Context / Components / Storage | H34: Requirement analysis + state sketch | I34: Design ready | J34: Diagram/notes + DDD | K34: Walk through design | L34: Explain why state belongs where | M34: Keep only verified decisions | N34: HIGH | O34: 30 | P34: TODO | Q34: DONE
A35: P2-12 | B35: Phase 2 – Design | C35: Day 2 | D35: Design Decision Record | E35: At least 5 decisions with alternatives, trade-offs and change impact. | F35: R02–R10; Rubric 2 | G35: Navigation / Context / Components / Storage | H35: Requirement analysis + state sketch | I35: Design ready | J35: Diagram/notes + DDD | K35: Walk through design | L35: Explain why state belongs where | M35: Keep only verified decisions | N35: HIGH | O35: 30 | P35: TODO | Q35: DONE
A36: P3-01 | B36: Phase 3 – Build (M1–M7) | C36: Day 3–6 | D36: M1 Project setup | E36: Verify clean install, Expo run and baseline build. | F36: R01–R10; Rubric 3 | G36: Project / Screens / Components / Context / Storage | H36: Design artifacts + code | I36: Working implementation | J36: Git/screenshot/test evidence | K36: Relevant test case | L36: Purpose → input → trigger → transform → output → failure | M36: Code ideas/debug hypotheses | N36: Run and verify independently | O36: HIGH | P36: 30 | Q36: DONE
A37: P3-02 | B37: Phase 3 – Build (M1–M7) | C37: Day 3–6 | D37: M1 Navigation skeleton | E37: Implement Home/Profile/Edit Profile/Activity/Settings navigation. | F37: R01–R10; Rubric 3 | G37: Project / Screens / Components / Context / Storage | H37: Design artifacts + code | I37: Working implementation | J37: Git/screenshot/test evidence | K37: Relevant test case | L37: Purpose → input → trigger → transform → output → failure | M37: Code ideas/debug hypotheses | N37: Run and verify independently | O37: HIGH | P37: 30 | Q37: DONE
A38: P3-03 | B38: Phase 3 – Build (M1–M7) | C38: Day 3–6 | D38: M1 Navigation verification | E38: Navigate every screen and save evidence. | F38: R01–R10; Rubric 3 | G38: Project / Screens / Components / Context / Storage | H38: Design artifacts + code | I38: Working implementation | J38: Git/screenshot/test evidence | K38: Relevant test case | L38: Purpose → input → trigger → transform → output → failure | M38: Code ideas/debug hypotheses | N38: Run and verify independently | O38: HIGH | P38: 30 | Q38: DONE
A39: P3-04 | B39: Phase 3 – Build (M1–M7) | C39: Day 3–6 | D39: M2 Base UI structure | E39: Build screen shells and reusable layout patterns. | F39: R01–R10; Rubric 3 | G39: Project / Screens / Components / Context / Storage | H39: Design artifacts + code | I39: Working implementation | J39: Git/screenshot/test evidence | K39: Relevant test case | L39: Purpose → input → trigger → transform → output → failure | M39: Code ideas/debug hypotheses | N39: Run and verify independently | O39: HIGH | P39: 30 | Q39: DONE
A40: P3-05 | B40: Phase 3 – Build (M1–M7) | C40: Day 3–6 | D40: M2 Reusable components | E40: Create reusable buttons, inputs, cards/list items. | F40: R01–R10; Rubric 3 | G40: Project / Screens / Components / Context / Storage | H40: Design artifacts + code | I40: Working implementation | J40: Git/screenshot/test evidence | K40: Relevant test case | L40: Purpose → input → trigger → transform → output → failure | M40: Code ideas/debug hypotheses | N40: Run and verify independently | O40: HIGH | P40: 30 | Q40: DONE
...

Sheet RTM
A1: Requirement ID | B1: Requirement | C1: Screen | D1: Component | E1: Code/File | F1: Implementation Status | G1: Test Case ID | H1: Evidence | I1: Demo Flow | J1: Interview Topic | K1: Notes
A2: R01 | B2: Project runs in clean environment | C2: App | D2: App root | E2: package.json / README | F2: DONE | G2: TC01 | H2: Clean-run screenshot/log | I2: Cold start | J2: Dependencies + run flow
A3: R02 | B3: Navigation ≥5 screens/areas | C3: All | D3: Navigation | E3: App navigation config | F3: DONE | G3: TC12 | H3: Navigation evidence | I3: Home → Profile → Edit → Activity → Settings | J3: Navigation responsibilities
A4: R03 | B4: Profile displays saved name/avatar/bio | C4: Profile | D4: Profile UI | E4: ProfileScreen | F4: DONE | G4: TC02 | H4: Profile screenshot | I4: Profile read | J4: Props/state/shared profile
A5: R04 | B5: Edit Profile controlled form + validation + save/cancel | C5: Edit Profile | D5: Inputs/Button | E5: EditProfileScreen | F5: DONE | G5: TC03,TC04,TC05 | H5: Validation + save evidence | I5: Profile → Edit → Save/Cancel | J5: Controlled form
A6: R05 | B6: Theme/preference shared with Context | C6: Settings/All | D6: ThemeContext | E6: ThemeContext / Provider | F6: DONE | G6: TC06,TC07 | H6: Theme + restart evidence | I6: Settings → toggle → other screen | J6: Context/rerender
A7: R06 | B7: FlatList + empty state (dummyjson.com API, search, tags, pagination) | C7: Activity | D7: List item | E7: Activity screen | F7: DONE | G7: TC08,TC09,TC10 | H7: List/empty screenshots | I7: Activity → interact | J7: renderItem/keyExtractor | K7: FlatList implemented in ActivityScreen & HomeScreen with API, search, tag filters, pagination, empty state. SectionList omitted.
A8: R07 | B8: AsyncStorage persistence | C8: App/Profile/Settings | D8: ProfileContext / ThemeContext | E8: src/contexts/ProfileContext.js, src/contexts/ThemeContext.js | F8: DONE | G8: TC07,TC11 | H8: Restart evidence | I8: Save → restart | J8: Hydration/serialization | K8: Persisted in ProfileContext (@user_profile) and ThemeContext (@app_theme). Standalone storage helper omitted.
A9: R08 | B9: Reusable components | C9: Multiple | D9: CardItem / CardShortCut | E9: src/components/CardItem.jsx, src/components/CardShortCut.jsx | F9: DONE | G9: TC12 | H9: Component usage | I9: Multiple screens | J9: Reuse/props | K9: CardItem (activity post card) & CardShortCut (navigation shortcut card) used across screens.
A10: R09 | B10: Responsive Flexbox/style | C10: All | D10: Layout | E10: StyleSheet/styles | F10: DONE | G10: TC01,TC16 | H10: Device evidence | I10: Run on emulator/device | J10: Flexbox
A11: R10 | B11: Error/fallback state | C11: Edit/Activity/Startup | D11: Validation/Empty/Fallback | E11: Screens + storage | F11: DONE | G11: TC03,TC09,TC11 | H11: Error/empty/fallback | I11: Invalid/empty/corrupt | J11: Failure path

Sheet Design_Decision_Record
A1: Decision ID | B1: Area | C1: Problem | D1: Chosen Solution | E1: Alternative | F1: Reason | G1: Trade-off | H1: Impact if Requirement Changes | I1: Related Screen | J1: Related Code | K1: Status
A2: D01 | B2: Navigation | C2: Need ≥5 screens/areas | D2: Central navigation configuration | E2: Separate navigation per screen | F2: Central responsibility | G2: Adds route config | H2: New screens modify central map | I2: All | J2: Navigation config | K2: DONE
A3: D02 | B3: State ownership | C3: Local vs shared state | D3: Local UI state; shared profile/theme in Context | E3: Prop drilling | F3: Matches scope | G3: Context rerenders consumers | H3: New shared state may need provider | I3: Profile/Edit/Settings | J3: Context + screens | K3: DONE
A4: D03 | B4: Persistence/hydration | C4: Survive restart + tolerate corrupt data | D4: AsyncStorage calls inside ProfileContext & ThemeContext with startup hydration + safe defaults | E4: Direct storage calls in screens | F4: Centralized handling | G4: Hydration complexity | H4: Storage backend can change behind helper | I4: App/Profile/Settings | J4: src/contexts/ProfileContext.js, src/contexts/ThemeContext.js | K4: DONE
A5: D04 | B5: List structure | C5: Collection + empty state required | D5: FlatList + stable keyExtractor + reusable item | E5: Map rendering | F5: Matches requirement | G5: More setup | H5: Grouping may require SectionList | I5: Activity | J5: Activity + item | K5: DONE
A6: D05 | B6: Reuse | C6: Repeated UI can drift | D6: Shared components with props | E6: Duplicate UI | F6: Consistency + reuse evidence | G6: Generic props need design | H6: New variants may expand API | I6: Multiple | J6: components/ | K6: DONE
A7: D06 | B7: Validation | C7: Invalid data must not persist | D7: Validate before save | E7: Validate after save | F7: Protects persisted state | G7: More form logic | H7: New fields need rules/tests | I7: Edit Profile | J7: EditProfileScreen | K7: DONE

Sheet Test_Matrix
A1: Test ID | B1: Group | C1: Case | D1: Preconditions | E1: Steps | F1: Expected Result | G1: Actual Result | H1: Status | I1: Bug ID | J1: Retest Result | K1: Evidence
A2: TC01 | B2: Startup | C2: First run | D2: Fresh install/no stored data | E2: Launch app | F2: Safe defaults; no crash | G2: Safe default profile (TrangTTT) and theme (light) loaded cleanly on cold start; no crash. | H2: PASSED | K2: App.js, ProfileContext.js, ThemeContext.js
A3: TC02 | B3: Profile | C3: Profile Read | D3: Profile has saved/default data | E3: Open Profile | F3: Name/avatar/bio render | G3: Profile name, email, bio, and avatar rendered accurately from ProfileContext. | H3: PASSED | K3: ProfileScreen.jsx
A4: TC03 | B4: Profile | C4: Edit Invalid | D4: Edit open | E4: Enter invalid data → Save | F4: Validation shown; invalid data not persisted | G4: Formik + Yup schema validation blocked save and rendered red error text under invalid fields. | H4: PASSED | K4: EditProfileScreen.jsx, ProfileSchema.js
A5: TC04 | B5: Profile | C5: Edit Valid | D5: Edit open | E5: Enter valid data → Save | F5: Data saves; Profile updates without restart | G5: Valid inputs updated ProfileContext, saved JSON to AsyncStorage (@user_profile), displayed Toast, and navigated back. | H5: PASSED | K5: EditProfileScreen.jsx, ProfileContext.js
A6: TC05 | B6: Profile | C6: Edit Cancel | D6: Edit open | E6: Change values → Cancel | F6: Saved profile unchanged | G6: Cancel button called navigation.goBack(); saved profile remained intact without mutation. | H6: PASSED | K6: EditProfileScreen.jsx
A7: TC06 | B7: Theme | C7: Theme Toggle | D7: Settings available | E7: Toggle theme/preference | F7: App-wide UI updates | G7: Toggling theme in SettingsScreen updated ThemeContext to dark/light, saved preference to AsyncStorage (@app_theme), and re-themed UI. | H7: PASSED | K7: SettingsScreen.jsx, ThemeContext.js
A8: TC07 | B8: Persistence | C8: Theme/Profile Persistence | D8: Saved state exists | E8: Change → restart → reopen | F8: State survives restart | G8: Saved profile details and active theme preference persisted and hydrated successfully across app restarts. | H8: PASSED | K8: ProfileContext.js, ThemeContext.js
A9: TC08 | B9: List | C9: List Normal | D9: Activity data exists | E9: Open Activity | F9: Items render with stable keys | G9: FlatList rendered post items fetched from dummyjson.com API with title, body, tags, likes, views using keyExtractor. | H9: PASSED | K9: ActivityScreen.jsx, activityService.js, CardItem.jsx
A10: TC09 | B10: List | C10: List Empty | D10: Activity data empty | E10: Open Activity | F10: Empty state; no crash | G10: ListEmptyComponent rendered No Activities Found icon and placeholder text when search/filter returned 0 items. | H10: PASSED | K10: ActivityScreen.jsx
A11: TC10 | B11: List | C11: List Interaction | D11: Activity loaded | E11: Use state-changing interaction | F11: List/UI updates | G11: Toggling Heart icon on post cards dynamically updated local like reaction state and counts in real-time. | H11: PASSED | K11: CardItem.jsx, ActivityScreen.jsx, HomeScreen.jsx
A12: TC11 | B12: Storage | C12: Storage Corrupt/Missing | D12: Storage missing/malformed | E12: Launch/read state | F12: Fallback/defaults; no crash | G12: Try-catch error handling in ProfileContext and ThemeContext caught corrupted/missing AsyncStorage data and restored safe default state. | H12: PASSED | K12: ProfileContext.js, ThemeContext.js
A13: TC12 | B13: Navigation | C13: All Screens | D13: App running | E13: Navigate all required areas | F13: All reachable/back works | G13: React Navigation transitioned smoothly across all 5 screens (Home, Activity, Profile, EditProfile, Settings) via Stack and Tab navigators. | H13: PASSED | K13: AppNavigator.js
... A18: TC17 | B18: Regression | C18: Runtime/Console | D18: Final build | E18: Run core workflow | F18: No serious errors | G18: Full application workflow executed without unhandled exceptions or console errors. | H18: PASSED | K18: App runtime log

Sheet Interview_Preparation
A1: Question | B1: What I should answer | C1: Code/file to open | D1: ≤30 sec explanation | E1: Practice status
A2: What is a component and why split UI? | B2: Focused UI responsibility; reusable/composable. | C2: Screen + components/ | D2: Purpose → props → state → output → failure. | E2: DONE
A3: How do props, state and Context differ? | B3: Props pass data; state belongs to component; Context shares selected state. | C3: Screen + Context | D3: Who owns data and why. | E3: DONE
A4: Why does changing state rerender? | B4: React updates UI from changed state. | C4: State-owning component | D4: State → render → UI. | E4: DONE
A5: Why not mutate state directly? | B5: Use a new value and setter so React can detect intended update. | C5: List/profile state | D5: Immutable update example. | E5: DONE
A6: Why keyExtractor? | B6: Stable keys let list rendering track items correctly. | C6: Activity | D6: Item → stable key → rendering. | E6: DONE
A7: How does controlled form work? | B7: Input value comes from state; onChange updates state. | C7: EditProfile | D7: Input → state → validate → save. | E7: DONE
A8: How does validation prevent bad persistence? | B8: Validate before save; reject invalid data. | C8: EditProfile | D8: Validate → reject or save. | E8: DONE
A9: Why Context for theme/profile? | B9: Shared across screens and should update consumers. | C9: Contexts | D9: Provider → consumers. | E9: DONE
A10: How does AsyncStorage persistence work? | B10: Serialize on save; deserialize on read; hydrate startup; fallback on failure. | C10: Storage helper/provider | D10: Save → JSON → storage; startup → parse → state. | E10: DONE
A11: What if storage is null/invalid JSON? | B11: Treat as missing/corrupt and use safe defaults. | C11: Storage helper | D11: Read → validate/parse → fallback. | E11: DONE
A12: New screen needs profile data—what changes? | B12: Consume shared Profile Context instead of duplicate state. | C12: New screen + ProfileContext | D12: Existing provider owns profile. | E12: DONE
... A17: Explain one real debug case. | B17: Symptom, expected/actual, hypothesis, checks, root cause, fix, retest. | C17: Debug_Log + code | D17: 30-sec summary then details. | E17: DONE

Sheet Transfer_Practice
A1: Change request | B1: Screen affected | C1: Component affected | D1: State affected | E1: Data affected | F1: Service/storage affected | G1: UI affected | H1: Tests affected | I1: Impact analysis | J1: Implementation | K1: Retest
A2: Basic: Add phone/location | B2: Profile + Edit | C2: Profile/inputs | D2: profile + form | E2: phone/location | F2: AsyncStorage/profile model | G2: Profile + Edit | H2: Read/edit/validation/persistence | I2: Model + validation + storage + UI + tests | J2: Implemented: Added phone & location to ProfileContext, ProfileSchema validation, ProfileScreen UI, and EditProfileScreen inputs. | K2: PASSED: Tested edit, validation, AsyncStorage save, and restart persistence.
A3: Basic: Reset form | B3: Edit Profile | C3: Reset button | D3: form + errors | E3: none | F3: none | G3: Reset controls | H3: Edit invalid/valid/cancel | I3: Clear form/errors without changing saved profile | J3: PLANNED | K3: PLANNED
A4: Basic: Filter activity/interests | B4: Activity | C4: Filter + item | D4: filter + list | E4: filtered collection | F4: none | G4: Filter UI | H4: List normal/empty/interaction | I4: Add filter state and derive visible data | J4: PLANNED | K4: PLANNED
A5: Basic: Change validation rule | B5: Edit Profile | C5: Input/error | D5: form/error | E5: profile field | F5: storage unchanged | G5: Error text | H5: Invalid/valid/cancel | I5: Update rule + tests | J5: PLANNED | K5: PLANNED
A6: Medium: Favorites + persistence | B6: Activity | C6: Favorite control | D6: favorites | E6: favorite IDs | F6: AsyncStorage | G6: Favorite indicator | H6: Interaction + persistence | I6: State + storage + hydration + tests | J6: PLANNED | K6: PLANNED
A7: Medium: System theme | B7: Settings/All | C7: ThemeContext | D7: theme | E7: preference | F7: storage/system | G7: Theme UI | H7: Theme/persistence | I7: Change source of truth while preserving consumers | J7: PLANNED | K7: PLANNED
A8: Medium: Separate storage helper | B8: All persistent | C8: Storage utility | D8: persistence flow | E8: serialized objects | F8: AsyncStorage helper | G8: No direct UI change | H8: Persistence/corrupt | I8: Move storage calls behind helper and retest | J8: PLANNED | K8: PLANNED
A9: Medium: Sort/group list | B9: Activity | C9: List + item | D9: derived list | E9: collection order/groups | F9: none | G9: Headers/order | H9: Normal/empty/interaction | I9: Verify keys and empty state | J9: PLANNED | K9: PLANNED
A10: Advanced: Mock authentication | B10: App/Profile | C10: Auth screens/context | D10: auth | E10: session | F10: mock persistence | G10: Login/logout | H10: Navigation/persistence | I10: Shared auth + protected flow | J10: PLANNED | K10: PLANNED
A11: Advanced: Mock API | B11: Profile/Activity | C11: Service layer | D11: loading/error/data | E11: API-shaped data | F11: mock API | G11: Loading/error UI | H11: Service + edge cases | I11: Add async boundary while preserving UI contract | J11: PLANNED | K11: PLANNED
A12: Advanced: Offline draft | B12: Edit Profile | C12: Draft controls | D12: draft + saved profile | E12: draft data | F12: AsyncStorage | G12: Draft recovery | H12: Form + restart | I12: Separate draft from saved profile | J12: PLANNED | K12: PLANNED

Sheet AI_Usage_Log
A1: ID | B1: Date | C1: Task | D1: Prompt | E1: Purpose | F1: AI Output | G1: What I Used | H1: What I Changed | I1: Verification Method | J1: Test Result | K1: Final Decision
A2: AI-01 | B2: 46297 | C2: Requirement analysis | D2: Review the Assignment 1 PDF and convert all requirements R01–R10 into a Requirement Traceability Matrix (RTM). For each requirement, identify the expected feature/behavior, the actual file/component in my React Native project that satisfies it, and the minimum test/evidence needed to verify it. Use the assignment PDF as the source of truth and do not invent requirements. | E2: Traceability & completeness check | F2: Structured RTM mapping for R01-R10 | G2: RTM requirement breakdown | H2: Mapped exact codebase file paths (AppNavigator, ProfileContext, etc.) | I2: Compared PDF guide against source code | J2: PASS | K2: Accepted & Verified
A3: AI-02 | B3: 46297 | C3: Design reasoning | D3: Review my Assignment 1 architecture and help me reason about state ownership and persistence. Analyze which state should be local to a screen/component, which state should be shared through Context, and which state should persist through AsyncStorage. Explain the trade-offs and produce Design Decision Record entries for the chosen navigation, state ownership, persistence/hydration, list structure, and component reuse decisions. | E3: Structure Design Decision Record (DDD) | F3: 6 architectural decision trade-offs (D01-D06) | G3: Core state & persistence trade-offs | H3: Refined D03 to reflect Context-based AsyncStorage persistence | I3: Inspected codebase architecture | J3: PASS | K3: Accepted & Verified
A4: AI-05 | B4: 46298 | C4: Code explanation | D4: Prepare concise 30-second interview answers for the React Native concepts I need to explain in Assignment 1. Focus on concepts that can be demonstrated directly in my codebase: component/props/state, re-rendering, Context and Provider/Consumer, controlled forms, Formik/Yup validation, navigation, FlatList, renderItem, keyExtractor, state mutation, AsyncStorage persistence/hydration, reusable components, and the Profile/Activity data flow. Anchor each explanation to the actual project instead of giving only textbook definitions. | E4: Interview preparation | F4: Answers for 17 interview questions | G4: Core technical concepts | H4: Anchored explanations to specific codebase file locations | I4: Mock self-interview using codebase | J4: PASS | K4: Accepted & Verified
A5: AI-06 | B5: 46298 | C5: Transfer practice | D5: Analyze impact and code changes for adding phone/location fields | E5: Implement Basic Transfer task | F5: Impact analysis across model, schema, UI, and storage | G5: Full impact analysis list | H5: Implemented phone & location in ProfileContext, ProfileSchema, ProfileScreen, EditProfileScreen | I5: Tested edit form save and AsyncStorage reload | J5: PASS | K5: Accepted & Verified
A6: AI-07 | B6: 46298 | C6: Execution flow / Code explanation | D6: Tôi là người mới học React Native và muốn tìm hiểu rõ quy luật thực thi của chương trình theo từng bước (step by step). Hãy phân tích quy luật thực thi của ứng dụng trong Assignment 1 và hiển thị workflow thực thi dưới dạng: method() → method() → method() → .... Bắt đầu từ khi tôi chạy npm start, cho đến khi ứng dụng nạp dữ liệu và hiển thị dữ liệu lên List. Hãy giải thích chi tiết từng bước và từng dòng lệnh quan trọng để giúp tôi hiểu được quá trình thực thi thực tế của chương trình. Lưu ý quan trọng: Mọi phân tích phải bắt đầu từ App.js trước, sau đó đi từ từ xuống các component, navigator, screen, context, service, storage/helper... theo đúng luồng thực thi thực tế của project. Không được nhảy thẳng vào một file hoặc method ở giữa. Hãy chỉ ra rõ: File nào được chạy trước. Method/function nào được gọi. Method nào gọi method nào. Dữ liệu được lấy từ đâu. Dữ liệu đi qua những file/function nào. Cuối cùng dữ liệu được đưa vào List và render lên UI như thế nào. Mục tiêu: Tôi muốn hiểu được toàn bộ execution flow của ứng dụng từ lúc npm start → App.js → các thành phần bên dưới → lấy dữ liệu → xử lý dữ liệu → render dữ liệu lên List, thay vì chỉ biết từng file riêng lẻ làm gì. | E6: Understand the actual runtime and data-execution flow instead of memorizing individual files | F6: Step-by-step flow from npm start → Expo/Metro → index.js → App() → providers → navigation → screen → useEffect() → service → Axios → API → state → FlatList → renderItem() → reusable card → UI | G6: Used the flow to prepare code explanation/demo and connect individual files into one execution chain | H6: Traced the actual project source from entry point through App, navigation, contexts, screens, service and FlatList; compared expected flow with runtime behavior | I6: PASS | J6: Accepted & Verified
A7: AI-08 | B7: 46301 | C7: Professional engineering / List design | D7: Continue: I want to understand professional problems and engineering practices used by large software companies, professional software projects, and production e-commerce projects. Please explain the design and use of ListView/list components in a real e-commerce project, specifically how they are applied and used in production. Relate the explanation to React Native FlatList and the current Assignment 1 implementation. | E7: Understand how the current academic FlatList implementation relates to production-scale list design | F7: Explained list responsibilities such as data source, item rendering, keys, pagination/infinite loading, refresh, loading/empty/error states, performance, state ownership and reusable item components; connected concepts to e-commerce catalog/product-list scenarios | G7: Professional list-design concepts that can be applied when explaining the current FlatList implementation | H7: No unnecessary production features were added to Assignment 1; used the concepts mainly for understanding, code explanation and future design reasoning | I7: Compared professional concepts against current HomeScreen/ActivityScreen, FlatList, CardItem, API service, search/filter and pagination implementation; checked against Assignment 1 list requirements | J7: PASS | K7: Accepted for learning/design reasoning; no unnecessary code change
A8: AI-09 | B8: 2026-10-03 / 2026-10-05 | C8: Documentation / README | D8: Review and structure an English README for MMA301 Assignment 1 covering features, architecture, navigation, state ownership, AsyncStorage, Formik/Yup, Axios/DummyJSON, FlatList, requirements and limitations | E8: Produce submission-ready project documentation | F8: README structure and concise descriptions of architecture, features, persistence, API/list behavior and limitations | G8: Documentation structure and technical descriptions | H8: Adapted the README to the actual project rather than copying generic architecture; added actual project features and implementation details | I8: Compared README statements with source code and assignment requirements | J8: PASS | K8: Accepted & Verified
A9: AI-10 | B9: 2026-10-02 → 2026-10-05 | C9: Runtime debugging / troubleshooting | D9: Analyze React Native runtime/import/state issues encountered during Assignment 1, including component import/export problems, profile data/state issues and development-environment problems | E9: Diagnose actual runtime/build issues without blindly changing unrelated code | F9: Root-cause hypotheses and targeted fixes for issues such as CardShortCut import/export, profile.name null handling, and Windows case-only file rename behavior | G9: Applied only fixes that matched the actual source/error and project structure | H9: Re-ran the affected screen/workflow and checked imports/state behavior after each fix | I9: PASS | J9: Accepted & Verified
A10: AI-11 | B10: 2026-10-05 → 2026-10-06 | C10: Final verification / engineering practice | D10: Review the Assignment 1 finalization process from testing, debugging and verification through README, Test Matrix, Debug Logs, AI Usage Log and final demo preparation | E10: Ensure the submission evidence is complete and consistent with the assignment guide | F10: Final verification checklist and recommended relationship between test evidence, debug logs, AI log, README and Git history | G10: Used the checklist to organize final evidence instead of changing working features unnecessarily | H10: Cross-checked submission artifacts against Assignment 1 requirements and actual project state | I10: PASS* | J10: Accepted; final evidence must reflect actual executed tests

Sheet Final_Checklist
A1: Section | B1: Checklist Item | C1: Checkbox | D1: Status | E1: Evidence | F1: Notes
A2: Technical | B2: App runs clean | C2: ☑ | D2: DONE | E2: App.js, package.json
A3: Technical | B3: ≥5 screens/areas | C3: ☑ | D3: DONE | E3: AppNavigator.js (5 screens)
A4: Technical | B4: Navigation verified | C4: ☑ | D4: DONE | E4: AppNavigator.js
A5: Technical | B5: Profile read works | C5: ☑ | D5: DONE | E5: ProfileScreen.jsx
A6: Technical | B6: Edit form works | C6: ☑ | D6: DONE | E6: EditProfileScreen.jsx
A7: Technical | B7: Validation blocks invalid save | C7: ☑ | D7: DONE | E7: ProfileSchema.js, EditProfileScreen.jsx
A8: Technical | B8: Cancel preserves saved data | C8: ☑ | D8: DONE | E8: EditProfileScreen.jsx
A9: Technical | B9: Theme/preference app-wide | C9: ☑ | D9: DONE | E9: ThemeContext.js, SettingsScreen.jsx
A10: Technical | B10: FlatList/SectionList | C10: ☑ | D10: DONE | E10: ActivityScreen.jsx, HomeScreen.jsx
A11: Technical | B11: Empty state | C11: ☑ | D11: DONE | E11: ActivityScreen.jsx (ListEmptyComponent)
A12: Technical | B12: AsyncStorage persistence | C12: ☑ | D12: DONE | E12: ProfileContext.js, ThemeContext.js
A13: Technical | B13: Restart persistence | C13: ☑ | D13: DONE | E13: ProfileContext.js, ThemeContext.js
... A39: Final Demo | B39: Evidence easy to locate | C39: ☑ | D39: DONE | E39: Workbook & source repo

Sheet Overview
A1: Metric | B1: Value | C1: Notes
A2: Total Tasks | B2: =COUNTA(MMA301_Assignment1_Plan!A2:A500) -> 74 | C2: Main plan | E2: CÁCH DÙNG FILE
A3: TODO | B3: =COUNTIF(MMA301_Assignment1_Plan!Q2:Q500,"TODO") -> 0 | C3: Not started | E3: ① Làm theo MMA301_Assignment1_Plan. ② Cập nhật Status + Evidence sau mỗi task. ③ Test thật thì điền Actual Result + Status. ④ Interview: luyện trả lời bằng chính code của mình. ⑤ Transfer: ghi impact → implementation → retest.
A4: DOING | B4: =COUNTIF(MMA301_Assignment1_Plan!Q2:Q500,"DOING") -> 0 | C4: In progress
A5: DONE | B5: =COUNTIF(MMA301_Assignment1_Plan!Q2:Q500,"DONE") -> 73 | C5: Completed
A6: BLOCKED | B6: =COUNTIF(MMA301_Assignment1_Plan!Q2:Q500,"BLOCKED") -> 0 | C6: Blocked
A7: Progress % | B7: =IFERROR(B5/B2,0) -> 0.98648649 | C7: DONE / total
A8: HIGH Priority | B8: =COUNTIF(MMA301_Assignment1_Plan!O2:O500,"HIGH") -> 55 | C8: High priority
A9: MEDIUM Priority | B9: =COUNTIF(MMA301_Assignment1_Plan!O2:O500,"MEDIUM") -> 7 | C9: Medium priority
A10: LOW Priority | B10: =COUNTIF(MMA301_Assignment1_Plan!O2:O500,"LOW") -> 0 | C10: Low priority
A11: RTM Requirements | B11: =COUNTA(RTM!A2:A50) -> 10 | C11: R01–R10
A12: Rubric Areas | B12: =COUNTA(RTM!A2:A50) -> 10 | C12: Rubric 1–8
A13: Test Cases | B13: =COUNTA(Test_Matrix!A2:A100) -> 17 | C13: Required + extra
A14: Debug Logs | B14: 2 | C14: Practice + real placeholders
A15: Transfer Tasks | B15: =COUNTA(Transfer_Practice!A2:A100) -> 11 | C15: Basic/Medium/Advanced
A18: Tasks by Phase
A19: Phase 1 – Requirement Analysis | B19: =COUNTIF(MMA301_Assignment1_Plan!B2:B500,A19) -> 22 | C19: Main plan task count
A20: Phase 2 – Design | B20: =COUNTIF(MMA301_Assignment1_Plan!B2:B500,A20) -> 12 | C20: Main plan task count
A21: Phase 3 – Build (M1–M7) | B21: =COUNTIF(MMA301_Assignment1_Plan!B2:B500,A21) -> 28 | C21: Main plan task count
A22: Phase 4 – Testing | B22: =COUNTIF(MMA301_Assignment1_Plan!B2:B500,A22) -> 2 | C22: Main plan task count
A23: Phase 5 – Debugging | B23: =COUNTIF(MMA301_Assignment1_Plan!B2:B500,A23) -> 2 | C23: Main plan task count
A24: Phase 6 – Interview | B24: =COUNTIF(MMA301_Assignment1_Plan!B2:B500,A24) -> 2 | C24: Main plan task count
A25: Phase 7 – Transfer | B25: =COUNTIF(MMA301_Assignment1_Plan!B2:B500,A25) -> 2 | C25: Main plan task count
A27: Evidence gaps to watch
A28: Actual Test Results | B28: =COUNTIF(Test_Matrix!G2:G100,"<>") -> 17 | C28: Fill after executing tests
A29: Real Debug Logs | B29: 2 | C29: Replace placeholders with real root causes
A30: Final Checklist DONE | B30: =COUNTIF(Final_Checklist!D2:D100,"DONE") -> 38 | C30: Complete before submission
A31: Interview DONE | B31: =COUNTIF(Interview_Preparation!E2:E100,"DONE") -> 16 | C31: Practice without reading
